Workbook
Name DeployStatus: Lists!$C$2:$C$8
Name DepStatus: Lists!$F$2:$F$8
Name DepType: Lists!$G$2:$G$3
Name DevStatus: Lists!$A$2:$A$9
Name Layer: Lists!$E$2:$E$4
Name Priority: Lists!$D$2:$D$4
Name QAStatus: Lists!$B$2:$B$8

Sheet Summary
A1: Phase 5 - Sprint Summary
A2: Sprint | B2: Weeks | C2: Dates | D2: Milestone | E2: Tasks | F2: FE Done | G2: BE Done | H2: QA Passed | I2: STG Deployed | J2: Prod Deployed | K2: Blocked | L2: % Complete | M2: Deps | N2: External Deps | O2: Deps Open
A3: P5-S1 | B3: 11-12 | C3: 21-Sep - 02-Oct-2026 | D3: Milestone 1 | E3: =COUNTA('P5-S1'!C3:C34) -> 32 | F3: =COUNTIF('P5-S1'!G3:G34,"Completed") -> 31 | G3: =COUNTIF('P5-S1'!H3:H34,"Completed") -> 32 | H3: =COUNTIF('P5-S1'!I3:I34,"Passed") -> 0 | I3: =COUNTIF('P5-S1'!J3:J34,"Deployed")+COUNTIF('P5-S1'!J3:J34,"Verified") -> 32 | J3: =COUNTIF('P5-S1'!K3:K34,"Deployed")+COUNTIF('P5-S1'!K3:K34,"Verified") -> 0 | K3: =COUNTIF('P5-S1'!G3:G34,"Blocked")+COUNTIF('P5-S1'!H3:H34,"Blocked") -> 0 | L3: =IFERROR((F3+G3)/(2*E3),0) -> 0.984375 | M3: =COUNTIF(Dependencies!$B$3:$B$76,A3) -> 12 | N3: =COUNTIFS(Dependencies!$B$3:$B$76,A3,Dependencies!$E$3:$E$76,"External") -> 2 | O3: =COUNTIFS(Dependencies!$B$3:$B$76,A3,Dependencies!$I$3:$I$76,"Not Started")+COUNTIFS(Dependencies!$B$3:$B$76,A3,Dependencies!$I$3:$I$76,"Requested")+COUNTIFS(Dependencies!$B$3:$B$76,A3,Dependencies!$I$3:$I$76,"In Progress")+COUNTIFS(Dependencies!$B$3:$B$76,A3,Dependencies!$I$3:$I$76,"At Risk")+COUNTIFS(Dependencies!$B$3:$B$76,A3,Dependencies!$I$3:$I$76,"Blocked") -> 9
A4: P5-S2 | B4: 13-14 | C4: 05-Oct - 16-Oct-2026 | D4: Milestone 2 | E4: =COUNTA('P5-S2'!C3:C25) -> 23 | F4: =COUNTIF('P5-S2'!G3:G25,"Completed") -> 0 | G4: =COUNTIF('P5-S2'!H3:H25,"Completed") -> 0 | H4: =COUNTIF('P5-S2'!I3:I25,"Passed") -> 0 | I4: =COUNTIF('P5-S2'!J3:J25,"Deployed")+COUNTIF('P5-S2'!J3:J25,"Verified") -> 0 | J4: =COUNTIF('P5-S2'!K3:K25,"Deployed")+COUNTIF('P5-S2'!K3:K25,"Verified") -> 0 | K4: =COUNTIF('P5-S2'!G3:G25,"Blocked")+COUNTIF('P5-S2'!H3:H25,"Blocked") -> 0 | L4: =IFERROR((F4+G4)/(2*E4),0) -> 0 | M4: =COUNTIF(Dependencies!$B$3:$B$76,A4) -> 12 | N4: =COUNTIFS(Dependencies!$B$3:$B$76,A4,Dependencies!$E$3:$E$76,"External") -> 6 | O4: =COUNTIFS(Dependencies!$B$3:$B$76,A4,Dependencies!$I$3:$I$76,"Not Started")+COUNTIFS(Dependencies!$B$3:$B$76,A4,Dependencies!$I$3:$I$76,"Requested")+COUNTIFS(Dependencies!$B$3:$B$76,A4,Dependencies!$I$3:$I$76,"In Progress")+COUNTIFS(Dependencies!$B$3:$B$76,A4,Dependencies!$I$3:$I$76,"At Risk")+COUNTIFS(Dependencies!$B$3:$B$76,A4,Dependencies!$I$3:$I$76,"Blocked") -> 10
A5: P5-S3 | B5: 15-16 | C5: 19-Oct - 30-Oct-2026 | D5: Milestone 3 | E5: =COUNTA('P5-S3'!C3:C33) -> 31 | F5: =COUNTIF('P5-S3'!G3:G33,"Completed") -> 0 | G5: =COUNTIF('P5-S3'!H3:H33,"Completed") -> 0 | H5: =COUNTIF('P5-S3'!I3:I33,"Passed") -> 0 | I5: =COUNTIF('P5-S3'!J3:J33,"Deployed")+COUNTIF('P5-S3'!J3:J33,"Verified") -> 0 | J5: =COUNTIF('P5-S3'!K3:K33,"Deployed")+COUNTIF('P5-S3'!K3:K33,"Verified") -> 0 | K5: =COUNTIF('P5-S3'!G3:G33,"Blocked")+COUNTIF('P5-S3'!H3:H33,"Blocked") -> 0 | L5: =IFERROR((F5+G5)/(2*E5),0) -> 0 | M5: =COUNTIF(Dependencies!$B$3:$B$76,A5) -> 10 | N5: =COUNTIFS(Dependencies!$B$3:$B$76,A5,Dependencies!$E$3:$E$76,"External") -> 2 | O5: =COUNTIFS(Dependencies!$B$3:$B$76,A5,Dependencies!$I$3:$I$76,"Not Started")+COUNTIFS(Dependencies!$B$3:$B$76,A5,Dependencies!$I$3:$I$76,"Requested")+COUNTIFS(Dependencies!$B$3:$B$76,A5,Dependencies!$I$3:$I$76,"In Progress")+COUNTIFS(Dependencies!$B$3:$B$76,A5,Dependencies!$I$3:$I$76,"At Risk")+COUNTIFS(Dependencies!$B$3:$B$76,A5,Dependencies!$I$3:$I$76,"Blocked") -> 10
A6: P5-S4 | B6: 17-18 | C6: 02-Nov - 13-Nov-2026 | D6: Milestone 3 | E6: =COUNTA('P5-S4'!C3:C36) -> 34 | F6: =COUNTIF('P5-S4'!G3:G36,"Completed") -> 0 | G6: =COUNTIF('P5-S4'!H3:H36,"Completed") -> 0 | H6: =COUNTIF('P5-S4'!I3:I36,"Passed") -> 0 | I6: =COUNTIF('P5-S4'!J3:J36,"Deployed")+COUNTIF('P5-S4'!J3:J36,"Verified") -> 0 | J6: =COUNTIF('P5-S4'!K3:K36,"Deployed")+COUNTIF('P5-S4'!K3:K36,"Verified") -> 0 | K6: =COUNTIF('P5-S4'!G3:G36,"Blocked")+COUNTIF('P5-S4'!H3:H36,"Blocked") -> 0 | L6: =IFERROR((F6+G6)/(2*E6),0) -> 0 | M6: =COUNTIF(Dependencies!$B$3:$B$76,A6) -> 15 | N6: =COUNTIFS(Dependencies!$B$3:$B$76,A6,Dependencies!$E$3:$E$76,"External") -> 11 | O6: =COUNTIFS(Dependencies!$B$3:$B$76,A6,Dependencies!$I$3:$I$76,"Not Started")+COUNTIFS(Dependencies!$B$3:$B$76,A6,Dependencies!$I$3:$I$76,"Requested")+COUNTIFS(Dependencies!$B$3:$B$76,A6,Dependencies!$I$3:$I$76,"In Progress")+COUNTIFS(Dependencies!$B$3:$B$76,A6,Dependencies!$I$3:$I$76,"At Risk")+COUNTIFS(Dependencies!$B$3:$B$76,A6,Dependencies!$I$3:$I$76,"Blocked") -> 15
A7: P5-S5 | B7: 19-20 | C7: 16-Nov - 27-Nov-2026 | D7: Milestone 4 | E7: =COUNTA('P5-S5'!C3:C32) -> 30 | F7: =COUNTIF('P5-S5'!G3:G32,"Completed") -> 0 | G7: =COUNTIF('P5-S5'!H3:H32,"Completed") -> 0 | H7: =COUNTIF('P5-S5'!I3:I32,"Passed") -> 0 | I7: =COUNTIF('P5-S5'!J3:J32,"Deployed")+COUNTIF('P5-S5'!J3:J32,"Verified") -> 0 | J7: =COUNTIF('P5-S5'!K3:K32,"Deployed")+COUNTIF('P5-S5'!K3:K32,"Verified") -> 0 | K7: =COUNTIF('P5-S5'!G3:G32,"Blocked")+COUNTIF('P5-S5'!H3:H32,"Blocked") -> 0 | L7: =IFERROR((F7+G7)/(2*E7),0) -> 0 | M7: =COUNTIF(Dependencies!$B$3:$B$76,A7) -> 12 | N7: =COUNTIFS(Dependencies!$B$3:$B$76,A7,Dependencies!$E$3:$E$76,"External") -> 5 | O7: =COUNTIFS(Dependencies!$B$3:$B$76,A7,Dependencies!$I$3:$I$76,"Not Started")+COUNTIFS(Dependencies!$B$3:$B$76,A7,Dependencies!$I$3:$I$76,"Requested")+COUNTIFS(Dependencies!$B$3:$B$76,A7,Dependencies!$I$3:$I$76,"In Progress")+COUNTIFS(Dependencies!$B$3:$B$76,A7,Dependencies!$I$3:$I$76,"At Risk")+COUNTIFS(Dependencies!$B$3:$B$76,A7,Dependencies!$I$3:$I$76,"Blocked") -> 10
A8: P5-S6 | B8: 21-22 | C8: 30-Nov - 11-Dec-2026 | D8: Go-Live | E8: =COUNTA('P5-S6'!C3:C29) -> 27 | F8: =COUNTIF('P5-S6'!G3:G29,"Completed") -> 0 | G8: =COUNTIF('P5-S6'!H3:H29,"Completed") -> 0 | H8: =COUNTIF('P5-S6'!I3:I29,"Passed") -> 0 | I8: =COUNTIF('P5-S6'!J3:J29,"Deployed")+COUNTIF('P5-S6'!J3:J29,"Verified") -> 0 | J8: =COUNTIF('P5-S6'!K3:K29,"Deployed")+COUNTIF('P5-S6'!K3:K29,"Verified") -> 0 | K8: =COUNTIF('P5-S6'!G3:G29,"Blocked")+COUNTIF('P5-S6'!H3:H29,"Blocked") -> 0 | L8: =IFERROR((F8+G8)/(2*E8),0) -> 0 | M8: =COUNTIF(Dependencies!$B$3:$B$76,A8) -> 13 | N8: =COUNTIFS(Dependencies!$B$3:$B$76,A8,Dependencies!$E$3:$E$76,"External") -> 4 | O8: =COUNTIFS(Dependencies!$B$3:$B$76,A8,Dependencies!$I$3:$I$76,"Not Started")+COUNTIFS(Dependencies!$B$3:$B$76,A8,Dependencies!$I$3:$I$76,"Requested")+COUNTIFS(Dependencies!$B$3:$B$76,A8,Dependencies!$I$3:$I$76,"In Progress")+COUNTIFS(Dependencies!$B$3:$B$76,A8,Dependencies!$I$3:$I$76,"At Risk")+COUNTIFS(Dependencies!$B$3:$B$76,A8,Dependencies!$I$3:$I$76,"Blocked") -> 13
A9: TOTAL | E9: =SUM(E3:E8) -> 177 | F9: =SUM(F3:F8) -> 31 | G9: =SUM(G3:G8) -> 32 | H9: =SUM(H3:H8) -> 0 | I9: =SUM(I3:I8) -> 32 | J9: =SUM(J3:J8) -> 0 | K9: =SUM(K3:K8) -> 0 | L9: =IFERROR((F9+G9)/(2*E9),0) -> 0.1779661 | M9: =SUM(M3:M8) -> 74 | N9: =SUM(N3:N8) -> 30 | O9: =SUM(O3:O8) -> 67

Sheet Master Tracker
A1: Master Tracker - all sprints
A2: S.No | B2: Sprint | C2: Module | D2: Task Name | E2: BRD Ref | F2: Layer | G2: Priority | H2: FE Status | I2: BE Status | J2: QA / UAT | K2: STG Deploy | L2: Prod Deploy | M2: Owner | N2: Target Date | O2: Remarks
A3: 1 | B3: P5-S1 | C3: RBAC Defaults & Filters | D3: Default permission set - Job object | E3: 4.3 | F3: Full Stack | G3: High | H3: =IF('P5-S1'!G3="","",'P5-S1'!G3) -> Completed | I3: =IF('P5-S1'!H3="","",'P5-S1'!H3) -> Completed | J3: =IF('P5-S1'!I3="","",'P5-S1'!I3) -> Not Started | K3: =IF('P5-S1'!J3="","",'P5-S1'!J3) -> Deployed | L3: =IF('P5-S1'!K3="","",'P5-S1'!K3) -> Not Deployed | M3: =IF('P5-S1'!L3="","",'P5-S1'!L3) -> Gokul | N3: =IF('P5-S1'!M3="","",'P5-S1'!M3) | O3: =IF('P5-S1'!N3="","",'P5-S1'!N3)
A4: 2 | B4: P5-S1 | C4: RBAC Defaults & Filters | D4: Default permission set - Candidate object | E4: 4.3 | F4: Full Stack | G4: High | H4: =IF('P5-S1'!G4="","",'P5-S1'!G4) -> Completed | I4: =IF('P5-S1'!H4="","",'P5-S1'!H4) -> Completed | J4: =IF('P5-S1'!I4="","",'P5-S1'!I4) -> Not Started | K4: =IF('P5-S1'!J4="","",'P5-S1'!J4) -> Deployed | L4: =IF('P5-S1'!K4="","",'P5-S1'!K4) -> Not Deployed | M4: =IF('P5-S1'!L4="","",'P5-S1'!L4) -> Gokul | N4: =IF('P5-S1'!M4="","",'P5-S1'!M4) | O4: =IF('P5-S1'!N4="","",'P5-S1'!N4)
A5: 3 | B5: P5-S1 | C5: RBAC Defaults & Filters | D5: Default permission set - Application object | E5: 4.3 | F5: Full Stack | G5: High | H5: =IF('P5-S1'!G5="","",'P5-S1'!G5) -> Completed | I5: =IF('P5-S1'!H5="","",'P5-S1'!H5) -> Completed | J5: =IF('P5-S1'!I5="","",'P5-S1'!I5) -> Not Started | K5: =IF('P5-S1'!J5="","",'P5-S1'!J5) -> Deployed | L5: =IF('P5-S1'!K5="","",'P5-S1'!K5) -> Not Deployed | M5: =IF('P5-S1'!L5="","",'P5-S1'!L5) -> Gokul | N5: =IF('P5-S1'!M5="","",'P5-S1'!M5) | O5: =IF('P5-S1'!N5="","",'P5-S1'!N5)
A6: 4 | B6: P5-S1 | C6: RBAC Defaults & Filters | D6: Role-driven dynamic search filters | E6: 4.3 | F6: Full Stack | G6: High | H6: =IF('P5-S1'!G6="","",'P5-S1'!G6) -> Completed | I6: =IF('P5-S1'!H6="","",'P5-S1'!H6) -> Completed | J6: =IF('P5-S1'!I6="","",'P5-S1'!I6) -> Not Started | K6: =IF('P5-S1'!J6="","",'P5-S1'!J6) -> Deployed | L6: =IF('P5-S1'!K6="","",'P5-S1'!K6) -> Not Deployed | M6: =IF('P5-S1'!L6="","",'P5-S1'!L6) -> Ehthikash | N6: =IF('P5-S1'!M6="","",'P5-S1'!M6) | O6: =IF('P5-S1'!N6="","",'P5-S1'!N6)
A7: 5 | B7: P5-S1 | C7: RBAC Defaults & Filters | D7: Candidate visibility restriction - recruiter / LOB / location | E7: 4.3 | F7: Full Stack | G7: High | H7: =IF('P5-S1'!G7="","",'P5-S1'!G7) -> Completed | I7: =IF('P5-S1'!H7="","",'P5-S1'!H7) -> Completed | J7: =IF('P5-S1'!I7="","",'P5-S1'!I7) -> Not Started | K7: =IF('P5-S1'!J7="","",'P5-S1'!J7) -> Deployed | L7: =IF('P5-S1'!K7="","",'P5-S1'!K7) -> Not Deployed | M7: =IF('P5-S1'!L7="","",'P5-S1'!L7) -> Ehthikash | N7: =IF('P5-S1'!M7="","",'P5-S1'!M7) | O7: =IF('P5-S1'!N7="","",'P5-S1'!N7)
A8: 6 | B8: P5-S1 | C8: RBAC Defaults & Filters | D8: Recruiter ownership & shared-candidate access | E8: 4.3 | F8: Backend | G8: High | H8: =IF('P5-S1'!G8="","",'P5-S1'!G8) -> Completed | I8: =IF('P5-S1'!H8="","",'P5-S1'!H8) -> Completed | J8: =IF('P5-S1'!I8="","",'P5-S1'!I8) -> Not Started | K8: =IF('P5-S1'!J8="","",'P5-S1'!J8) -> Deployed | L8: =IF('P5-S1'!K8="","",'P5-S1'!K8) -> Not Deployed | M8: =IF('P5-S1'!L8="","",'P5-S1'!L8) -> Ehthikash | N8: =IF('P5-S1'!M8="","",'P5-S1'!M8) | O8: =IF('P5-S1'!N8="","",'P5-S1'!N8)
A9: 7 | B9: P5-S1 | C9: RBAC Defaults & Filters | D9: Elevated visibility for TL / Manager | E9: 4.3 | F9: Full Stack | G9: High | H9: =IF('P5-S1'!G9="","",'P5-S1'!G9) -> Completed | I9: =IF('P5-S1'!H9="","",'P5-S1'!H9) -> Completed | J9: =IF('P5-S1'!I9="","",'P5-S1'!I9) -> Not Started | K9: =IF('P5-S1'!J9="","",'P5-S1'!J9) -> Deployed | L9: =IF('P5-S1'!K9="","",'P5-S1'!K9) -> Not Deployed | M9: =IF('P5-S1'!L9="","",'P5-S1'!L9) -> Ehthikash | N9: =IF('P5-S1'!M9="","",'P5-S1'!M9) | O9: =IF('P5-S1'!N9="","",'P5-S1'!N9)
A10: 8 | B10: P5-S1 | C10: RBAC Defaults & Filters | D10: Override access with approver authorization | E10: 4.3 | F10: Full Stack | G10: Medium | H10: =IF('P5-S1'!G10="","",'P5-S1'!G10) -> Completed | I10: =IF('P5-S1'!H10="","",'P5-S1'!H10) -> Completed | J10: =IF('P5-S1'!I10="","",'P5-S1'!I10) -> Not Started | K10: =IF('P5-S1'!J10="","",'P5-S1'!J10) -> Deployed | L10: =IF('P5-S1'!K10="","",'P5-S1'!K10) -> Not Deployed | M10: =IF('P5-S1'!L10="","",'P5-S1'!L10) -> Ehthikash | N10: =IF('P5-S1'!M10="","",'P5-S1'!M10) | O10: =IF('P5-S1'!N10="","",'P5-S1'!N10)
A11: 9 | B11: P5-S1 | C11: Logging & Timestamp | D11: Central logging framework | E11: 4.21 | F11: Backend | G11: High | H11: =IF('P5-S1'!G11="","",'P5-S1'!G11) -> Completed | I11: =IF('P5-S1'!H11="","",'P5-S1'!H11) -> Completed | J11: =IF('P5-S1'!I11="","",'P5-S1'!I11) -> Not Started | K11: =IF('P5-S1'!J11="","",'P5-S1'!J11) -> Deployed | L11: =IF('P5-S1'!K11="","",'P5-S1'!K11) -> Not Deployed | M11: =IF('P5-S1'!L11="","",'P5-S1'!L11) -> Harish | N11: =IF('P5-S1'!M11="","",'P5-S1'!M11) | O11: =IF('P5-S1'!N11="","",'P5-S1'!N11)
A12: 10 | B12: P5-S1 | C12: Logging & Timestamp | D12: Timestamp logs | E12: 4.21 | F12: Backend | G12: High | H12: =IF('P5-S1'!G12="","",'P5-S1'!G12) -> Completed | I12: =IF('P5-S1'!H12="","",'P5-S1'!H12) -> Completed | J12: =IF('P5-S1'!I12="","",'P5-S1'!I12) -> Not Started | K12: =IF('P5-S1'!J12="","",'P5-S1'!J12) -> Deployed | L12: =IF('P5-S1'!K12="","",'P5-S1'!K12) -> Not Deployed | M12: =IF('P5-S1'!L12="","",'P5-S1'!L12) -> Harish | N12: =IF('P5-S1'!M12="","",'P5-S1'!M12) | O12: =IF('P5-S1'!N12="","",'P5-S1'!N12)
A13: 11 | B13: P5-S1 | C13: Logging & Timestamp | D13: Approval logs | E13: 4.21 | F13: Backend | G13: High | H13: =IF('P5-S1'!G13="","",'P5-S1'!G13) -> Completed | I13: =IF('P5-S1'!H13="","",'P5-S1'!H13) -> Completed | J13: =IF('P5-S1'!I13="","",'P5-S1'!I13) -> Not Started | K13: =IF('P5-S1'!J13="","",'P5-S1'!J13) -> Deployed | L13: =IF('P5-S1'!K13="","",'P5-S1'!K13) -> Not Deployed | M13: =IF('P5-S1'!L13="","",'P5-S1'!L13) -> Harish | N13: =IF('P5-S1'!M13="","",'P5-S1'!M13) | O13: =IF('P5-S1'!N13="","",'P5-S1'!N13)
A14: 12 | B14: P5-S1 | C14: Logging & Timestamp | D14: Workflow transition logs | E14: 4.21 | F14: Backend | G14: High | H14: =IF('P5-S1'!G14="","",'P5-S1'!G14) -> Completed | I14: =IF('P5-S1'!H14="","",'P5-S1'!H14) -> Completed | J14: =IF('P5-S1'!I14="","",'P5-S1'!I14) -> Not Started | K14: =IF('P5-S1'!J14="","",'P5-S1'!J14) -> Deployed | L14: =IF('P5-S1'!K14="","",'P5-S1'!K14) -> Not Deployed | M14: =IF('P5-S1'!L14="","",'P5-S1'!L14) -> Aarthy | N14: =IF('P5-S1'!M14="","",'P5-S1'!M14) | O14: =IF('P5-S1'!N14="","",'P5-S1'!N14)
... A34: 32 | B34: P5-S1 | C34: Admin Module | D34: Restrict enterprise configuration to Admin | E34: 4.1 | F34: Backend | G34: High | H34: =IF('P5-S1'!G34="","",'P5-S1'!G34) -> Completed | I34: =IF('P5-S1'!H34="","",'P5-S1'!H34) -> Completed | J34: =IF('P5-S1'!I34="","",'P5-S1'!I34) -> Not Started | K34: =IF('P5-S1'!J34="","",'P5-S1'!J34) -> Deployed | L34: =IF('P5-S1'!K34="","",'P5-S1'!K34) -> Not Deployed | M34: =IF('P5-S1'!L34="","",'P5-S1'!L34) -> Gokul | N34: =IF('P5-S1'!M34="","",'P5-S1'!M34) | O34: =IF('P5-S1'!N34="","",'P5-S1'!N34)
A35: 33 | B35: P5-S2 | C35: Admin Module | D35: Secure credential / secret store | E35: 4.1 | F35: Backend | G35: High | H35: =IF('P5-S2'!G3="","",'P5-S2'!G3) -> In Progress | I35: =IF('P5-S2'!H3="","",'P5-S2'!H3) -> In Progress | J35: =IF('P5-S2'!I3="","",'P5-S2'!I3) -> Not Started | K35: =IF('P5-S2'!J3="","",'P5-S2'!J3) -> Not Deployed | L35: =IF('P5-S2'!K3="","",'P5-S2'!K3) -> Not Deployed | M35: =IF('P5-S2'!L3="","",'P5-S2'!L3) -> Gokul / Aarthy | N35: =IF('P5-S2'!M3="","",'P5-S2'!M3) | O35: =IF('P5-S2'!N3="","",'P5-S2'!N3)
A36: 34 | B36: P5-S2 | C36: Admin Module | D36: Secret access control & UI masking | E36: 4.1 | F36: Full Stack | G36: High | H36: =IF('P5-S2'!G4="","",'P5-S2'!G4) -> Not Started | I36: =IF('P5-S2'!H4="","",'P5-S2'!H4) -> In Progress | J36: =IF('P5-S2'!I4="","",'P5-S2'!I4) -> Not Started | K36: =IF('P5-S2'!J4="","",'P5-S2'!J4) -> Not Deployed | L36: =IF('P5-S2'!K4="","",'P5-S2'!K4) -> Not Deployed | M36: =IF('P5-S2'!L4="","",'P5-S2'!L4) -> Gokul | N36: =IF('P5-S2'!M4="","",'P5-S2'!M4) | O36: =IF('P5-S2'!N4="","",'P5-S2'!N4)
A37: 35 | B37: P5-S2 | C37: Admin Module | D37: Secret access logging | E37: 4.1 | F37: Backend | G37: High | H37: =IF('P5-S2'!G5="","",'P5-S2'!G5) -> Not Started | I37: =IF('P5-S2'!H5="","",'P5-S2'!H5) -> In Progress | J37: =IF('P5-S2'!I5="","",'P5-S2'!I5) -> Not Started | K37: =IF('P5-S2'!J5="","",'P5-S2'!J5) -> Not Deployed | L37: =IF('P5-S2'!K5="","",'P5-S2'!K5) -> Not Deployed | M37: =IF('P5-S2'!L5="","",'P5-S2'!L5) -> Gokul / Aarthy | N37: =IF('P5-S2'!M5="","",'P5-S2'!M5) | O37: =IF('P5-S2'!N5="","",'P5-S2'!N5)
A38: 36 | B38: P5-S2 | C38: Admin Module | D38: Encryption at rest and in transit | E38: NFR2 | F38: Backend | G38: High | H38: =IF('P5-S2'!G6="","",'P5-S2'!G6) -> Not Applicable | I38: =IF('P5-S2'!H6="","",'P5-S2'!H6) -> In Progress | J38: =IF('P5-S2'!I6="","",'P5-S2'!I6) -> Not Started | K38: =IF('P5-S2'!J6="","",'P5-S2'!J6) -> Not Deployed | L38: =IF('P5-S2'!K6="","",'P5-S2'!K6) -> Not Deployed | M38: =IF('P5-S2'!L6="","",'P5-S2'!L6) -> Gokul / Aarthy | N38: =IF('P5-S2'!M6="","",'P5-S2'!M6) | O38: =IF('P5-S2'!N6="","",'P5-S2'!N6)
A39: 37 | B39: P5-S2 | C39: Admin Module | D39: Role creation & permission assignment | E39: 4.1 | F39: Full Stack | G39: High | H39: =IF('P5-S2'!G7="","",'P5-S2'!G7) -> Not Started | I39: =IF('P5-S2'!H7="","",'P5-S2'!H7) -> In Progress | J39: =IF('P5-S2'!I7="","",'P5-S2'!I7) -> Not Started | K39: =IF('P5-S2'!J7="","",'P5-S2'!J7) -> Not Deployed | L39: =IF('P5-S2'!K7="","",'P5-S2'!K7) -> Not Deployed | M39: =IF('P5-S2'!L7="","",'P5-S2'!L7) -> Gokul | N39: =IF('P5-S2'!M7="","",'P5-S2'!M7) | O39: =IF('P5-S2'!N7="","",'P5-S2'!N7)
A40: 38 | B40: P5-S2 | C40: Admin Module | D40: Organizational approval hierarchy setup | E40: 4.1 | F40: Full Stack | G40: High | H40: =IF('P5-S2'!G8="","",'P5-S2'!G8) -> Not Started | I40: =IF('P5-S2'!H8="","",'P5-S2'!H8) -> In Progress | J40: =IF('P5-S2'!I8="","",'P5-S2'!I8) -> Not Started | K40: =IF('P5-S2'!J8="","",'P5-S2'!J8) -> Not Deployed | L40: =IF('P5-S2'!K8="","",'P5-S2'!K8) -> Not Deployed | M40: =IF('P5-S2'!L8="","",'P5-S2'!L8) -> Gokul | N40: =IF('P5-S2'!M8="","",'P5-S2'!M8) | O40: =IF('P5-S2'!N8="","",'P5-S2'!N8)
A41: 39 | B41: P5-S2 | C41: Admin Module | D41: Multi-level approver configuration | E41: 4.1 | F41: Full Stack | G41: High | H41: =IF('P5-S2'!G9="","",'P5-S2'!G9) -> Not Started | I41: =IF('P5-S2'!H9="","",'P5-S2'!H9) -> In Progress | J41: =IF('P5-S2'!I9="","",'P5-S2'!I9) -> Not Started | K41: =IF('P5-S2'!J9="","",'P5-S2'!J9) -> Not Deployed | L41: =IF('P5-S2'!K9="","",'P5-S2'!K9) -> Not Deployed | M41: =IF('P5-S2'!L9="","",'P5-S2'!L9) -> Gokul / Aarthy | N41: =IF('P5-S2'!M9="","",'P5-S2'!M9) | O41: =IF('P5-S2'!N9="","",'P5-S2'!N9)
A42: 40 | B42: P5-S2 | C42: Admin Module | D42: Enterprise-level configuration screen | E42: 4.1 | F42: Full Stack | G42: Medium | H42: =IF('P5-S2'!G10="","",'P5-S2'!G10) -> Not Started | I42: =IF('P5-S2'!H10="","",'P5-S2'!H10) -> In Progress | J42: =IF('P5-S2'!I10="","",'P5-S2'!I10) -> Not Started | K42: =IF('P5-S2'!J10="","",'P5-S2'!J10) -> Not Deployed | L42: =IF('P5-S2'!K10="","",'P5-S2'!K10) -> Not Deployed | M42: =IF('P5-S2'!L10="","",'P5-S2'!L10) -> Gokul / Aarthy | N42: =IF('P5-S2'!M10="","",'P5-S2'!M10) | O42: =IF('P5-S2'!N10="","",'P5-S2'!N10)
A43: 41 | B43: P5-S2 | C43: Admin Module | D43: Admin module role-based test matrix | E43: 4.1 | F43: Full Stack | G43: Medium | H43: =IF('P5-S2'!G11="","",'P5-S2'!G11) -> Not Started | I43: =IF('P5-S2'!H11="","",'P5-S2'!H11) -> Not Started | J43: =IF('P5-S2'!I11="","",'P5-S2'!I11) -> Not Started | K43: =IF('P5-S2'!J11="","",'P5-S2'!J11) -> Not Deployed | L43: =IF('P5-S2'!K11="","",'P5-S2'!K11) -> Not Deployed | M43: =IF('P5-S2'!L11="","",'P5-S2'!L11) -> Gokul | N43: =IF('P5-S2'!M11="","",'P5-S2'!M11) | O43: =IF('P5-S2'!N11="","",'P5-S2'!N11)
A44: 42 | B44: P5-S2 | C44: Assessment Integration | D44: Common assessment integration framework | E44: 4.8 | F44: Backend | G44: High | H44: =IF('P5-S2'!G12="","",'P5-S2'!G12) -> In Progress | I44: =IF('P5-S2'!H12="","",'P5-S2'!H12) -> In Progress | J44: =IF('P5-S2'!I12="","",'P5-S2'!I12) -> Not Started | K44: =IF('P5-S2'!J12="","",'P5-S2'!J12) -> Not Deployed | L44: =IF('P5-S2'!K12="","",'P5-S2'!K12) -> Not Deployed | M44: =IF('P5-S2'!L12="","",'P5-S2'!L12) -> Ehthikash | N44: =IF('P5-S2'!M12="","",'P5-S2'!M12) | O44: =IF('P5-S2'!N12="","",'P5-S2'!N12)
A45: 43 | B45: P5-S2 | C45: Assessment Integration | D45: Versant assessment invocation in workflow | E45: 4.8 | F45: Full Stack | G45: High | H45: =IF('P5-S2'!G13="","",'P5-S2'!G13) -> In Progress | I45: =IF('P5-S2'!H13="","",'P5-S2'!H13) -> In Progress | J45: =IF('P5-S2'!I13="","",'P5-S2'!I13) -> Not Started | K45: =IF('P5-S2'!J13="","",'P5-S2'!J13) -> Not Deployed | L45: =IF('P5-S2'!K13="","",'P5-S2'!K13) -> Not Deployed | M45: =IF('P5-S2'!L13="","",'P5-S2'!L13) -> Ehthikash | N45: =IF('P5-S2'!M13="","",'P5-S2'!M13) | O45: =IF('P5-S2'!N13="","",'P5-S2'!N13)
A46: 44 | B46: P5-S2 | C46: Assessment Integration | D46: Typing & other assessment integration | E46: 4.8 | F46: Full Stack | G46: Medium | H46: =IF('P5-S2'!G14="","",'P5-S2'!G14) -> Not Started | I46: =IF('P5-S2'!H14="","",'P5-S2'!H14) -> Not Started | J46: =IF('P5-S2'!I14="","",'P5-S2'!I14) -> Not Started | K46: =IF('P5-S2'!J14="","",'P5-S2'!J14) -> Not Deployed | L46: =IF('P5-S2'!K14="","",'P5-S2'!K14) -> Not Deployed | M46: =IF('P5-S2'!L14="","",'P5-S2'!L14) -> Harish / Aarthy | N46: =IF('P5-S2'!M14="","",'P5-S2'!M14) | O46: =IF('P5-S2'!N14="","",'P5-S2'!N14) -> What are the list of integrations needed.. Any preference.
... A57: 55 | B57: P5-S2 | C57: Blacklist Candidate | D57: Blacklist audit trail & un-blacklist approval | E57: Phase 5 backlog | F57: Full Stack | G57: Medium | H57: =IF('P5-S2'!G25="","",'P5-S2'!G25) -> Not Started | I57: =IF('P5-S2'!H25="","",'P5-S2'!H25) -> Not Started | J57: =IF('P5-S2'!I25="","",'P5-S2'!I25) -> Not Started | K57: =IF('P5-S2'!J25="","",'P5-S2'!J25) -> Not Deployed | L57: =IF('P5-S2'!K25="","",'P5-S2'!K25) -> Not Deployed | M57: =IF('P5-S2'!L25="","",'P5-S2'!L25) -> Livesh | N57: =IF('P5-S2'!M25="","",'P5-S2'!M25) | O57: =IF('P5-S2'!N25="","",'P5-S2'!N25)
A58: 56 | B58: P5-S3 | C58: Profile Details Modification | D58: Online registration form - mandatory & optional fields | E58: 4.4 | F58: Full Stack | G58: High | H58: =IF('P5-S3'!G3="","",'P5-S3'!G3) -> Not Started | I58: =IF('P5-S3'!H3="","",'P5-S3'!H3) -> Not Started | J58: =IF('P5-S3'!I3="","",'P5-S3'!I3) -> Not Started | K58: =IF('P5-S3'!J3="","",'P5-S3'!J3) -> Not Deployed | L58: =IF('P5-S3'!K3="","",'P5-S3'!K3) -> Not Deployed | M58: =IF('P5-S3'!L3="","",'P5-S3'!L3) | N58: =IF('P5-S3'!M3="","",'P5-S3'!M3) | O58: =IF('P5-S3'!N3="","",'P5-S3'!N3)
A59: 57 | B59: P5-S3 | C59: Profile Details Modification | D59: Data validation for identity & contact fields | E59: 4.4 | F59: Full Stack | G59: High | H59: =IF('P5-S3'!G4="","",'P5-S3'!G4) -> Not Started | I59: =IF('P5-S3'!H4="","",'P5-S3'!H4) -> Not Started | J59: =IF('P5-S3'!I4="","",'P5-S3'!I4) -> Not Started | K59: =IF('P5-S3'!J4="","",'P5-S3'!J4) -> Not Deployed | L59: =IF('P5-S3'!K4="","",'P5-S3'!K4) -> Not Deployed | M59: =IF('P5-S3'!L4="","",'P5-S3'!L4) | N59: =IF('P5-S3'!M4="","",'P5-S3'!M4) | O59: =IF('P5-S3'!N4="","",'P5-S3'!N4)
A60: 58 | B60: P5-S3 | C60: Profile Details Modification | D60: Stage-based profile update validation | E60: 4.4 | F60: Full Stack | G60: High | H60: =IF('P5-S3'!G5="","",'P5-S3'!G5) -> Not Started | I60: =IF('P5-S3'!H5="","",'P5-S3'!H5) -> Not Started | J60: =IF('P5-S3'!I5="","",'P5-S3'!I5) -> Not Started | K60: =IF('P5-S3'!J5="","",'P5-S3'!J5) -> Not Deployed | L60: =IF('P5-S3'!K5="","",'P5-S3'!K5) -> Not Deployed | M60: =IF('P5-S3'!L5="","",'P5-S3'!L5) | N60: =IF('P5-S3'!M5="","",'P5-S3'!M5) | O60: =IF('P5-S3'!N5="","",'P5-S3'!N5)
A61: 59 | B61: P5-S3 | C61: Profile Details Modification | D61: Field lock after applicant creation | E61: 4.4 | F61: Full Stack | G61: High | H61: =IF('P5-S3'!G6="","",'P5-S3'!G6) -> Not Started | I61: =IF('P5-S3'!H6="","",'P5-S3'!H6) -> Not Started | J61: =IF('P5-S3'!I6="","",'P5-S3'!I6) -> Not Started | K61: =IF('P5-S3'!J6="","",'P5-S3'!J6) -> Not Deployed | L61: =IF('P5-S3'!K6="","",'P5-S3'!K6) -> Not Deployed | M61: =IF('P5-S3'!L6="","",'P5-S3'!L6) | N61: =IF('P5-S3'!M6="","",'P5-S3'!M6) | O61: =IF('P5-S3'!N6="","",'P5-S3'!N6)
A62: 60 | B62: P5-S3 | C62: Profile Details Modification | D62: Candidate profile export to secure PDF | E62: 4.4 | F62: Full Stack | G62: Medium | H62: =IF('P5-S3'!G7="","",'P5-S3'!G7) -> Not Started | I62: =IF('P5-S3'!H7="","",'P5-S3'!H7) -> Not Started | J62: =IF('P5-S3'!I7="","",'P5-S3'!I7) -> Not Started | K62: =IF('P5-S3'!J7="","",'P5-S3'!J7) -> Not Deployed | L62: =IF('P5-S3'!K7="","",'P5-S3'!K7) -> Not Deployed | M62: =IF('P5-S3'!L7="","",'P5-S3'!L7) | N62: =IF('P5-S3'!M7="","",'P5-S3'!M7) | O62: =IF('P5-S3'!N7="","",'P5-S3'!N7)
A63: 61 | B63: P5-S3 | C63: Profile Details Modification | D63: Registration completion gate | E63: 4.4 | F63: Backend | G63: High | H63: =IF('P5-S3'!G8="","",'P5-S3'!G8) -> Not Started | I63: =IF('P5-S3'!H8="","",'P5-S3'!H8) -> Not Started | J63: =IF('P5-S3'!I8="","",'P5-S3'!I8) -> Not Started | K63: =IF('P5-S3'!J8="","",'P5-S3'!J8) -> Not Deployed | L63: =IF('P5-S3'!K8="","",'P5-S3'!K8) -> Not Deployed | M63: =IF('P5-S3'!L8="","",'P5-S3'!L8) | N63: =IF('P5-S3'!M8="","",'P5-S3'!M8) | O63: =IF('P5-S3'!N8="","",'P5-S3'!N8)
A64: 62 | B64: P5-S3 | C64: Applicant Changes | D64: Job re-mapping - 6 scenarios | E64: 4.6 | F64: Full Stack | G64: High | H64: =IF('P5-S3'!G9="","",'P5-S3'!G9) -> Not Started | I64: =IF('P5-S3'!H9="","",'P5-S3'!H9) -> Not Started | J64: =IF('P5-S3'!I9="","",'P5-S3'!I9) -> Not Started | K64: =IF('P5-S3'!J9="","",'P5-S3'!J9) -> Not Deployed | L64: =IF('P5-S3'!K9="","",'P5-S3'!K9) -> Not Deployed | M64: =IF('P5-S3'!L9="","",'P5-S3'!L9) | N64: =IF('P5-S3'!M9="","",'P5-S3'!M9) | O64: =IF('P5-S3'!N9="","",'P5-S3'!N9)
A65: 63 | B65: P5-S3 | C65: Applicant Changes | D65: Walk-In interview scheduling | E65: 4.6 | F65: Full Stack | G65: High | H65: =IF('P5-S3'!G10="","",'P5-S3'!G10) -> Not Started | I65: =IF('P5-S3'!H10="","",'P5-S3'!H10) -> Not Started | J65: =IF('P5-S3'!I10="","",'P5-S3'!I10) -> Not Started | K65: =IF('P5-S3'!J10="","",'P5-S3'!J10) -> Not Deployed | L65: =IF('P5-S3'!K10="","",'P5-S3'!K10) -> Not Deployed | M65: =IF('P5-S3'!L10="","",'P5-S3'!L10) | N65: =IF('P5-S3'!M10="","",'P5-S3'!M10) | O65: =IF('P5-S3'!N10="","",'P5-S3'!N10)
A66: 64 | B66: P5-S3 | C66: Applicant Changes | D66: Online interview scheduling | E66: 4.6 | F66: Full Stack | G66: High | H66: =IF('P5-S3'!G11="","",'P5-S3'!G11) -> Not Started | I66: =IF('P5-S3'!H11="","",'P5-S3'!H11) -> Not Started | J66: =IF('P5-S3'!I11="","",'P5-S3'!I11) -> Not Started | K66: =IF('P5-S3'!J11="","",'P5-S3'!J11) -> Not Deployed | L66: =IF('P5-S3'!K11="","",'P5-S3'!K11) -> Not Deployed | M66: =IF('P5-S3'!L11="","",'P5-S3'!L11) | N66: =IF('P5-S3'!M11="","",'P5-S3'!M11) | O66: =IF('P5-S3'!N11="","",'P5-S3'!N11)
A67: 65 | B67: P5-S3 | C67: Applicant Changes | D67: Reject applicant with template & remarks | E67: 4.6 | F67: Full Stack | G67: High | H67: =IF('P5-S3'!G12="","",'P5-S3'!G12) -> Not Started | I67: =IF('P5-S3'!H12="","",'P5-S3'!H12) -> Not Started | J67: =IF('P5-S3'!I12="","",'P5-S3'!I12) -> Not Started | K67: =IF('P5-S3'!J12="","",'P5-S3'!J12) -> Not Deployed | L67: =IF('P5-S3'!K12="","",'P5-S3'!K12) -> Not Deployed | M67: =IF('P5-S3'!L12="","",'P5-S3'!L12) | N67: =IF('P5-S3'!M12="","",'P5-S3'!M12) | O67: =IF('P5-S3'!N12="","",'P5-S3'!N12)
A68: 66 | B68: P5-S3 | C68: Applicant Changes | D68: Move applicant to HR Interview tab | E68: 4.6 | F68: Full Stack | G68: High | H68: =IF('P5-S3'!G13="","",'P5-S3'!G13) -> Not Started | I68: =IF('P5-S3'!H13="","",'P5-S3'!H13) -> Not Started | J68: =IF('P5-S3'!I13="","",'P5-S3'!I13) -> Not Started | K68: =IF('P5-S3'!J13="","",'P5-S3'!J13) -> Not Deployed | L68: =IF('P5-S3'!K13="","",'P5-S3'!K13) -> Not Deployed | M68: =IF('P5-S3'!L13="","",'P5-S3'!L13) | N68: =IF('P5-S3'!M13="","",'P5-S3'!M13) | O68: =IF('P5-S3'!N13="","",'P5-S3'!N13)
A69: 67 | B69: P5-S3 | C69: Applicant Changes | D69: Restrict actions to tagged recruiter & TL | E69: 4.6 | F69: Backend | G69: High | H69: =IF('P5-S3'!G14="","",'P5-S3'!G14) -> Not Started | I69: =IF('P5-S3'!H14="","",'P5-S3'!H14) -> Not Started | J69: =IF('P5-S3'!I14="","",'P5-S3'!I14) -> Not Started | K69: =IF('P5-S3'!J14="","",'P5-S3'!J14) -> Not Deployed | L69: =IF('P5-S3'!K14="","",'P5-S3'!K14) -> Not Deployed | M69: =IF('P5-S3'!L14="","",'P5-S3'!L14) | N69: =IF('P5-S3'!M14="","",'P5-S3'!M14) | O69: =IF('P5-S3'!N14="","",'P5-S3'!N14)
...

Sheet P5-S1
A1: P5-S1 | Weeks 11-12 | 21-Sep - 02-Oct-2026
A2: S.No | B2: Module | C2: Task Name | D2: BRD Ref | E2: Layer | F2: Priority | G2: FE Status | H2: BE Status | I2: QA / UAT | J2: STG Deploy | K2: Prod Deploy | L2: Owner | M2: Target Date | N2: Remarks
A3: 1 | B3: RBAC Defaults & Filters | C3: Default permission set - Job object | D3: 4.3 | E3: Full Stack | F3: High | G3: Completed | H3: Completed | I3: Not Started | J3: Deployed | K3: Not Deployed | L3: Gokul
A4: 2 | B4: RBAC Defaults & Filters | C4: Default permission set - Candidate object | D4: 4.3 | E4: Full Stack | F4: High | G4: Completed | H4: Completed | I4: Not Started | J4: Deployed | K4: Not Deployed | L4: Gokul
A5: 3 | B5: RBAC Defaults & Filters | C5: Default permission set - Application object | D5: 4.3 | E5: Full Stack | F5: High | G5: Completed | H5: Completed | I5: Not Started | J5: Deployed | K5: Not Deployed | L5: Gokul
A6: 4 | B6: RBAC Defaults & Filters | C6: Role-driven dynamic search filters | D6: 4.3 | E6: Full Stack | F6: High | G6: Completed | H6: Completed | I6: Not Started | J6: Deployed | K6: Not Deployed | L6: Ehthikash
A7: 5 | B7: RBAC Defaults & Filters | C7: Candidate visibility restriction - recruiter / LOB / location | D7: 4.3 | E7: Full Stack | F7: High | G7: Completed | H7: Completed | I7: Not Started | J7: Deployed | K7: Not Deployed | L7: Ehthikash
A8: 6 | B8: RBAC Defaults & Filters | C8: Recruiter ownership & shared-candidate access | D8: 4.3 | E8: Backend | F8: High | G8: Completed | H8: Completed | I8: Not Started | J8: Deployed | K8: Not Deployed | L8: Ehthikash
A9: 7 | B9: RBAC Defaults & Filters | C9: Elevated visibility for TL / Manager | D9: 4.3 | E9: Full Stack | F9: High | G9: Completed | H9: Completed | I9: Not Started | J9: Deployed | K9: Not Deployed | L9: Ehthikash
A10: 8 | B10: RBAC Defaults & Filters | C10: Override access with approver authorization | D10: 4.3 | E10: Full Stack | F10: Medium | G10: Completed | H10: Completed | I10: Not Started | J10: Deployed | K10: Not Deployed | L10: Ehthikash
A11: 9 | B11: Logging & Timestamp | C11: Central logging framework | D11: 4.21 | E11: Backend | F11: High | G11: Completed | H11: Completed | I11: Not Started | J11: Deployed | K11: Not Deployed | L11: Harish
A12: 10 | B12: Logging & Timestamp | C12: Timestamp logs | D12: 4.21 | E12: Backend | F12: High | G12: Completed | H12: Completed | I12: Not Started | J12: Deployed | K12: Not Deployed | L12: Harish
A13: 11 | B13: Logging & Timestamp | C13: Approval logs | D13: 4.21 | E13: Backend | F13: High | G13: Completed | H13: Completed | I13: Not Started | J13: Deployed | K13: Not Deployed | L13: Harish
A14: 12 | B14: Logging & Timestamp | C14: Workflow transition logs | D14: 4.21 | E14: Backend | F14: High | G14: Completed | H14: Completed | I14: Not Started | J14: Deployed | K14: Not Deployed | L14: Aarthy
... A34: 32 | B34: Admin Module | C34: Restrict enterprise configuration to Admin | D34: 4.1 | E34: Backend | F34: High | G34: Completed | H34: Completed | I34: Not Started | J34: Deployed | K34: Not Deployed | L34: Gokul

Sheet P5-S2
A1: P5-S2 | Weeks 13-14 | 05-Oct - 16-Oct-2026
A2: S.No | B2: Module | C2: Task Name | D2: BRD Ref | E2: Layer | F2: Priority | G2: FE Status | H2: BE Status | I2: QA / UAT | J2: STG Deploy | K2: Prod Deploy | L2: Owner | M2: Target Date | N2: Remarks
A3: 1 | B3: Admin Module | C3: Secure credential / secret store | D3: 4.1 | E3: Backend | F3: High | G3: In Progress | H3: In Progress | I3: Not Started | J3: Not Deployed | K3: Not Deployed | L3: Gokul / Aarthy
A4: 2 | B4: Admin Module | C4: Secret access control & UI masking | D4: 4.1 | E4: Full Stack | F4: High | G4: Not Started | H4: In Progress | I4: Not Started | J4: Not Deployed | K4: Not Deployed | L4: Gokul
A5: 3 | B5: Admin Module | C5: Secret access logging | D5: 4.1 | E5: Backend | F5: High | G5: Not Started | H5: In Progress | I5: Not Started | J5: Not Deployed | K5: Not Deployed | L5: Gokul / Aarthy
A6: 4 | B6: Admin Module | C6: Encryption at rest and in transit | D6: NFR2 | E6: Backend | F6: High | G6: Not Applicable | H6: In Progress | I6: Not Started | J6: Not Deployed | K6: Not Deployed | L6: Gokul / Aarthy
A7: 5 | B7: Admin Module | C7: Role creation & permission assignment | D7: 4.1 | E7: Full Stack | F7: High | G7: Not Started | H7: In Progress | I7: Not Started | J7: Not Deployed | K7: Not Deployed | L7: Gokul
A8: 6 | B8: Admin Module | C8: Organizational approval hierarchy setup | D8: 4.1 | E8: Full Stack | F8: High | G8: Not Started | H8: In Progress | I8: Not Started | J8: Not Deployed | K8: Not Deployed | L8: Gokul
A9: 7 | B9: Admin Module | C9: Multi-level approver configuration | D9: 4.1 | E9: Full Stack | F9: High | G9: Not Started | H9: In Progress | I9: Not Started | J9: Not Deployed | K9: Not Deployed | L9: Gokul / Aarthy
A10: 8 | B10: Admin Module | C10: Enterprise-level configuration screen | D10: 4.1 | E10: Full Stack | F10: Medium | G10: Not Started | H10: In Progress | I10: Not Started | J10: Not Deployed | K10: Not Deployed | L10: Gokul / Aarthy
A11: 9 | B11: Admin Module | C11: Admin module role-based test matrix | D11: 4.1 | E11: Full Stack | F11: Medium | G11: Not Started | H11: Not Started | I11: Not Started | J11: Not Deployed | K11: Not Deployed | L11: Gokul
A12: 10 | B12: Assessment Integration | C12: Common assessment integration framework | D12: 4.8 | E12: Backend | F12: High | G12: In Progress | H12: In Progress | I12: Not Started | J12: Not Deployed | K12: Not Deployed | L12: Ehthikash
A13: 11 | B13: Assessment Integration | C13: Versant assessment invocation in workflow | D13: 4.8 | E13: Full Stack | F13: High | G13: In Progress | H13: In Progress | I13: Not Started | J13: Not Deployed | K13: Not Deployed | L13: Ehthikash
A14: 12 | B14: Assessment Integration | C14: Typing assessment integration | D14: 4.8 | E14: Full Stack | F14: Medium | G14: Not Started | H14: Not Started | I14: Not Started | J14: Not Deployed | K14: Not Deployed | L14: Harish / Aarthy | N14: What are the list of integrations needed.. Any preference.
A15: 13 | B15: Assessment Integration | C15: Auto-trigger assessment links by LOB / role | D15: 4.8 | E15: Backend | F15: High | G15: Not Started | H15: In Progress | I15: Not Started | J15: Not Deployed | K15: Not Deployed | L15: Harish
A16: 14 | B16: Assessment Integration | C16: Capture results, timestamps & score validity | D16: 4.8 | E16: Backend | F16: High | G16: Not Started | H16: In Progress | I16: Not Started | J16: Not Deployed | K16: Not Deployed | L16: Harish
A17: 15 | B17: Assessment Integration | C17: 60-day score validity rule engine | D17: 4.7 / 4.8 | E17: Backend | F17: High | G17: Not Started | H17: In Progress | I17: Not Started | J17: Not Deployed | K17: Not Deployed | L17: Livesh
A18: 16 | B18: Assessment Integration | C18: Reschedule flow for technical issues | D18: 4.8 | E18: Full Stack | F18: Medium | G18: Not Started | H18: Not Started | I18: Not Started | J18: Not Deployed | K18: Not Deployed | L18: Ehthikash
A19: 17 | B19: Assessment Integration | C19: Approver authorization for technical reschedule | D19: 4.8 | E19: Full Stack | F19: Medium | G19: Not Started | H19: Not Started | I19: Not Started | J19: Not Deployed | K19: Not Deployed | L19: Ehthikash
A20: 18 | B20: Assessment Integration | C20: Cooling period rules - SHL assessments | D20: 4.8 | E20: Backend | F20: High | G20: Not Started | H20: In Progress | I20: Not Started | J20: Not Deployed | K20: Not Deployed | L20: Livesh
A21: 19 | B21: Assessment Integration | C21: Voice Fresher Chennai restriction | D21: 4.8 | E21: Backend | F21: High | G21: Not Started | H21: Not Started | I21: Not Started | J21: Not Deployed | K21: Not Deployed | L21: Harish / Aarthy
A22: 20 | B22: Assessment Integration | C22: Assessment audit logging | D22: 4.21 | E22: Backend | F22: Medium | G22: Not Applicable | H22: In Progress | I22: Not Started | J22: Not Deployed | K22: Not Deployed | L22: Harish
A23: 21 | B23: Blacklist Candidate | C23: Blacklist flag with reason capture | D23: Phase 5 backlog | E23: Full Stack | F23: Medium | G23: Not Started | H23: Not Started | I23: Not Started | J23: Not Deployed | K23: Not Deployed | L23: Livesh
A24: 22 | B24: Blacklist Candidate | C24: Block blacklisted candidate from registration / mapping | D24: Phase 5 backlog | E24: Full Stack | F24: Medium | G24: Not Started | H24: Not Started | I24: Not Started | J24: Not Deployed | K24: Not Deployed | L24: Livesh
A25: 23 | B25: Blacklist Candidate | C25: Blacklist audit trail & un-blacklist approval | D25: Phase 5 backlog | E25: Full Stack | F25: Medium | G25: Not Started | H25: Not Started | I25: Not Started | J25: Not Deployed | K25: Not Deployed | L25: Livesh

Sheet P5-S3
A1: P5-S3 | Weeks 15-16 | 19-Oct - 30-Oct-2026
A2: S.No | B2: Module | C2: Task Name | D2: BRD Ref | E2: Layer | F2: Priority | G2: FE Status | H2: BE Status | I2: QA / UAT | J2: STG Deploy | K2: Prod Deploy | L2: Owner | M2: Target Date | N2: Remarks
A3: 1 | B3: Profile Details Modification | C3: Online registration form - mandatory & optional fields | D3: 4.4 | E3: Full Stack | F3: High | G3: Not Started | H3: Not Started | I3: Not Started | J3: Not Deployed | K3: Not Deployed
A4: 2 | B4: Profile Details Modification | C4: Data validation for identity & contact fields | D4: 4.4 | E4: Full Stack | F4: High | G4: Not Started | H4: Not Started | I4: Not Started | J4: Not Deployed | K4: Not Deployed
A5: 3 | B5: Profile Details Modification | C5: Stage-based profile update validation | D5: 4.4 | E5: Full Stack | F5: High | G5: Not Started | H5: Not Started | I5: Not Started | J5: Not Deployed | K5: Not Deployed
A6: 4 | B6: Profile Details Modification | C6: Field lock after applicant creation | D6: 4.4 | E6: Full Stack | F6: High | G6: Not Started | H6: Not Started | I6: Not Started | J6: Not Deployed | K6: Not Deployed
A7: 5 | B7: Profile Details Modification | C7: Candidate profile export to secure PDF | D7: 4.4 | E7: Full Stack | F7: Medium | G7: Not Started | H7: Not Started | I7: Not Started | J7: Not Deployed | K7: Not Deployed
A8: 6 | B8: Profile Details Modification | C8: Registration completion gate | D8: 4.4 | E8: Backend | F8: High | G8: Not Started | H8: Not Started | I8: Not Started | J8: Not Deployed | K8: Not Deployed
A9: 7 | B9: Applicant Changes | C9: Job re-mapping - 6 scenarios | D9: 4.6 | E9: Full Stack | F9: High | G9: Not Started | H9: Not Started | I9: Not Started | J9: Not Deployed | K9: Not Deployed
A10: 8 | B10: Applicant Changes | C10: Walk-In interview scheduling | D10: 4.6 | E10: Full Stack | F10: High | G10: Not Started | H10: Not Started | I10: Not Started | J10: Not Deployed | K10: Not Deployed
A11: 9 | B11: Applicant Changes | C11: Online interview scheduling | D11: 4.6 | E11: Full Stack | F11: High | G11: Not Started | H11: Not Started | I11: Not Started | J11: Not Deployed | K11: Not Deployed
A12: 10 | B12: Applicant Changes | C12: Reject applicant with template & remarks | D12: 4.6 | E12: Full Stack | F12: High | G12: Not Started | H12: Not Started | I12: Not Started | J12: Not Deployed | K12: Not Deployed
A13: 11 | B13: Applicant Changes | C13: Move applicant to HR Interview tab | D13: 4.6 | E13: Full Stack | F13: High | G13: Not Started | H13: Not Started | I13: Not Started | J13: Not Deployed | K13: Not Deployed
A14: 12 | B14: Applicant Changes | C14: Restrict actions to tagged recruiter & TL | D14: 4.6 | E14: Backend | F14: High | G14: Not Started | H14: Not Started | I14: Not Started | J14: Not Deployed | K14: Not Deployed
... A33: 31 | B33: Map Candidate | C33: Active requisition validation on mapping | D33: 4.2 / 4.5 | E33: Backend | F33: High | G33: Not Started | H33: Not Started | I33: Not Started | J33: Not Deployed | K33: Not Deployed

Sheet P5-S4
A1: P5-S4 | Weeks 17-18 | 02-Nov - 13-Nov-2026
A2: S.No | B2: Module | C2: Task Name | D2: BRD Ref | E2: Layer | F2: Priority | G2: FE Status | H2: BE Status | I2: QA / UAT | J2: STG Deploy | K2: Prod Deploy | L2: Owner | M2: Target Date | N2: Remarks
A3: 1 | B3: ID Proof Verification | C3: ID proof upload with secure storage | D3: 4.14 | E3: Full Stack | F3: High | G3: Not Started | H3: Not Started | I3: Not Started | J3: Not Deployed | K3: Not Deployed
A4: 2 | B4: ID Proof Verification | C4: External Identity Verification API integration | D4: 4.14 | E4: Backend | F4: High | G4: Not Started | H4: Not Started | I4: Not Started | J4: Not Deployed | K4: Not Deployed
A5: 3 | B5: ID Proof Verification | C5: Validation badge for verified candidates | D5: 4.14 | E5: Full Stack | F5: Medium | G5: Not Started | H5: Not Started | I5: Not Started | J5: Not Deployed | K5: Not Deployed
A6: 4 | B6: ID Proof Verification | C6: Role-restricted access to ID documents | D6: 4.14 | E6: Full Stack | F6: High | G6: Not Started | H6: Not Started | I6: Not Started | J6: Not Deployed | K6: Not Deployed
A7: 5 | B7: ID Proof Verification | C7: Encryption at rest and in transit for ID documents | D7: 4.14 | E7: Backend | F7: High | G7: Not Started | H7: Not Started | I7: Not Started | J7: Not Deployed | K7: Not Deployed
A8: 6 | B8: Candidate ID & Photo Validation | C8: Manual photo verification screen for panelists | D8: 4.15 | E8: Full Stack | F8: High | G8: Not Started | H8: Not Started | I8: Not Started | J8: Not Deployed | K8: Not Deployed
A9: 7 | B9: Candidate ID & Photo Validation | C9: Panelist confirm / reject candidate identity | D9: 4.15 | E9: Full Stack | F9: High | G9: Not Started | H9: Not Started | I9: Not Started | J9: Not Deployed | K9: Not Deployed
A10: 8 | B10: Candidate ID & Photo Validation | C10: Auto-highlight photo mismatch rejections | D10: 4.15 | E10: Full Stack | F10: Medium | G10: Not Started | H10: Not Started | I10: Not Started | J10: Not Deployed | K10: Not Deployed
A11: 9 | B11: Offer Oracle Integration | C11: Candidate to Oracle Offer Interface field mapping | D11: 4.17 | E11: Backend | F11: High | G11: Not Started | H11: Not Started | I11: Not Started | J11: Not Deployed | K11: Not Deployed
A12: 10 | B12: Offer Oracle Integration | C12: Offer push API integration | D12: 4.17 | E12: Backend | F12: High | G12: Not Started | H12: Not Started | I12: Not Started | J12: Not Deployed | K12: Not Deployed
A13: 11 | B13: Offer Oracle Integration | C13: Pre-push offer validation | D13: 4.17 | E13: Full Stack | F13: High | G13: Not Started | H13: Not Started | I13: Not Started | J13: Not Deployed | K13: Not Deployed
A14: 12 | B14: Offer Oracle Integration | C14: Oracle status change to DigiHire status update | D14: 4.17 | E14: Backend | F14: High | G14: Not Started | H14: Not Started | I14: Not Started | J14: Not Deployed | K14: Not Deployed
... A36: 34 | B36: Job Integration / LOB Modification | C36: Job sync failure logging & retry | D36: 4.2 | E36: Backend | F36: Medium | G36: Not Started | H36: Not Started | I36: Not Started | J36: Not Deployed | K36: Not Deployed

Sheet P5-S5
A1: P5-S5 | Weeks 19-20 | 16-Nov - 27-Nov-2026
A2: S.No | B2: Module | C2: Task Name | D2: BRD Ref | E2: Layer | F2: Priority | G2: FE Status | H2: BE Status | I2: QA / UAT | J2: STG Deploy | K2: Prod Deploy | L2: Owner | M2: Target Date | N2: Remarks
A3: 1 | B3: HR Round (Online/Offline) | C3: Online interview mode | D3: 4.10 | E3: Full Stack | F3: High | G3: Not Started | H3: Not Started | I3: Not Started | J3: Not Deployed | K3: Not Deployed
A4: 2 | B4: HR Round (Online/Offline) | C4: In-Office interview mode | D4: 4.10 | E4: Full Stack | F4: High | G4: Not Started | H4: Not Started | I4: Not Started | J4: Not Deployed | K4: Not Deployed
A5: 3 | B5: HR Round (Online/Offline) | C5: Interview screenshot capture - Online | D5: 4.10 | E5: Full Stack | F5: High | G5: Not Started | H5: Not Started | I5: Not Started | J5: Not Deployed | K5: Not Deployed
A6: 4 | B6: HR Round (Online/Offline) | C6: Kiosk photo matching - In-Office | D6: 4.10 | E6: Full Stack | F6: High | G6: Not Started | H6: Not Started | I6: Not Started | J6: Not Deployed | K6: Not Deployed
A7: 5 | B7: HR Round (Online/Offline) | C7: Competency-based feedback configuration | D7: 4.10 | E7: Full Stack | F7: High | G7: Not Started | H7: Not Started | I7: Not Started | J7: Not Deployed | K7: Not Deployed
A8: 6 | B8: HR Round (Online/Offline) | C8: Feedback entry & scoring | D8: 4.10 | E8: Full Stack | F8: High | G8: Not Started | H8: Not Started | I8: Not Started | J8: Not Deployed | K8: Not Deployed
A9: 7 | B9: HR Round (Online/Offline) | C9: Movement to Panel based on feedback | D9: 4.10 | E9: Full Stack | F9: High | G9: Not Started | H9: Not Started | I9: Not Started | J9: Not Deployed | K9: Not Deployed
A10: 8 | B10: HR Round (Online/Offline) | C10: Movement to Assessment based on feedback | D10: 4.10 | E10: Full Stack | F10: High | G10: Not Started | H10: Not Started | I10: Not Started | J10: Not Deployed | K10: Not Deployed
A11: 9 | B11: HR Round (Online/Offline) | C11: Rejected candidate immediate move to Rejected tab | D11: 4.10 | E11: Full Stack | F11: High | G11: Not Started | H11: Not Started | I11: Not Started | J11: Not Deployed | K11: Not Deployed
A12: 10 | B12: HR Round (Online/Offline) | C12: Valid next-stage enforcement | D12: 4.10 | E12: Backend | F12: High | G12: Not Started | H12: Not Started | I12: Not Started | J12: Not Deployed | K12: Not Deployed
A13: 11 | B13: Panel Interview Enhancements | C13: Panel schedule creation - LOB, panelist, location, ORC ID | D13: 4.12 | E13: Full Stack | F13: High | G13: Not Started | H13: Not Started | I13: Not Started | J13: Not Deployed | K13: Not Deployed
A14: 12 | B14: Panel Interview Enhancements | C14: Recording upload | D14: 4.12 | E14: Full Stack | F14: High | G14: Not Started | H14: Not Started | I14: Not Started | J14: Not Deployed | K14: Not Deployed
... A32: 30 | B32: Vendor Module | C32: Three end-to-end vendor scenarios | D32: 8 (Acceptance) | E32: Full Stack | F32: High | G32: Not Started | H32: Not Started | I32: Not Started | J32: Not Deployed | K32: Not Deployed

Sheet P5-S6
A1: P5-S6 | Weeks 21-22 | 30-Nov - 11-Dec-2026
A2: S.No | B2: Module | C2: Task Name | D2: BRD Ref | E2: Layer | F2: Priority | G2: FE Status | H2: BE Status | I2: QA / UAT | J2: STG Deploy | K2: Prod Deploy | L2: Owner | M2: Target Date | N2: Remarks
A3: 1 | B3: Dashboard & Reporting | C3: Dashboard search & filter enhancements | D3: 4.20 | E3: Full Stack | F3: High | G3: Not Started | H3: Not Started | I3: Not Started | J3: Not Deployed | K3: Not Deployed
A4: 2 | B4: Dashboard & Reporting | C4: Drill-down from dashboard widgets | D4: 4.20 | E4: Full Stack | F4: High | G4: Not Started | H4: Not Started | I4: Not Started | J4: Not Deployed | K4: Not Deployed
A5: 3 | B5: Dashboard & Reporting | C5: Hiring funnel report | D5: 4.20 | E5: Full Stack | F5: High | G5: Not Started | H5: Not Started | I5: Not Started | J5: Not Deployed | K5: Not Deployed
A6: 4 | B6: Dashboard & Reporting | C6: Vendor performance report | D6: 4.20 | E6: Full Stack | F6: High | G6: Not Started | H6: Not Started | I6: Not Started | J6: Not Deployed | K6: Not Deployed
A7: 5 | B7: Dashboard & Reporting | C7: Recruiter performance report | D7: 4.20 | E7: Full Stack | F7: High | G7: Not Started | H7: Not Started | I7: Not Started | J7: Not Deployed | K7: Not Deployed
A8: 6 | B8: Dashboard & Reporting | C8: Report export - Excel / PDF | D8: 4.20 | E8: Full Stack | F8: Medium | G8: Not Started | H8: Not Started | I8: Not Started | J8: Not Deployed | K8: Not Deployed
A9: 7 | B9: Dashboard & Reporting | C9: Role-based dashboard & report access | D9: 4.20 / 4.3 | E9: Full Stack | F9: High | G9: Not Started | H9: Not Started | I9: Not Started | J9: Not Deployed | K9: Not Deployed
A10: 8 | B10: Dashboard & Reporting | C10: TL and above requisition upload / modify | D10: 4.20 | E10: Full Stack | F10: Medium | G10: Not Started | H10: Not Started | I10: Not Started | J10: Not Deployed | K10: Not Deployed
A11: 9 | B11: Dashboard & Reporting | C11: Report accuracy validation >=99% | D11: 8 (Acceptance) | E11: Full Stack | F11: High | G11: Not Started | H11: Not Started | I11: Not Started | J11: Not Deployed | K11: Not Deployed
A12: 10 | B12: Optimization & Tuning | C12: Map Candidate page optimization | D12: 4.23 | E12: Full Stack | F12: High | G12: Not Started | H12: Not Started | I12: Not Started | J12: Not Deployed | K12: Not Deployed
A13: 11 | B13: Optimization & Tuning | C13: Applicant page optimization | D13: 4.23 | E13: Full Stack | F13: High | G13: Not Started | H13: Not Started | I13: Not Started | J13: Not Deployed | K13: Not Deployed
A14: 12 | B14: Optimization & Tuning | C14: Dashboard load time reduction | D14: 4.23 / NFR1 | E14: Full Stack | F14: High | G14: Not Started | H14: Not Started | I14: Not Started | J14: Not Deployed | K14: Not Deployed
... A29: 27 | B29: Build Stabilization | C29: Production deployment & hypercare | D29: 9 (Deliverables) | E29: Full Stack | F29: High | G29: Not Started | H29: Not Started | I29: Not Started | J29: Not Deployed | K29: Not Deployed

Sheet Dependencies
A1: Sprint Dependency Register
A2: Dep ID | B2: Sprint | C2: Dependency | D2: Category | E2: Type | F2: Owner | G2: Team | H2: Required By | I2: Status | J2: Remarks
A3: DEP-S1-01 | B3: P5-S1 | C3: SMTP server & email template engine configuration | D3: Email Template | E3: External | F3: TA Head | G3: TA Head / Leadership | H3: Before 21-Sep | I3: Not Started | J3: Need confirmation whether we will be using the same set as before. Template will be handled in the code.
A4: DEP-S1-02 | B4: P5-S1 | C4: Email domain whitelisting (SPF / DKIM / DMARC) for candidate mails | D4: Infrastructure | E4: External | F4: AGS IT / Security | G4: AGS Security, Legal & Compliance | H4: Before 21-Sep | I4: Closed
A5: DEP-S1-03 | B5: P5-S1 | C5: Role, LOB and Location master data | D5: Data / Configuration | E5: Internal | F5: AGS TA Ops | G5: AGS TA Ops / BA | H5: Before 21-Sep | I5: Not Started
A6: DEP-S1-04 | B6: P5-S1 | C6: Signed-off RBAC permission matrix (role x object x action) | D6: Approval / Sign-off | E6: Internal | F6: TA Head / Suresh | G6: TA Head / Leadership | H6: Before 21-Sep | I6: Not Started
A7: DEP-S1-05 | B7: P5-S1 | C7: Log table schema, storage sizing & retention policy | D7: AGS Software | E7: Internal | F7: AGS Tech | G7: AGS IT & Infra | H7: Before 21-Sep | I7: Not Started | J7: Paddy can give these details.
A8: DEP-S1-06 | B8: P5-S1 | C8: STG environments provisioned for Phase 5 | D8: Environment | E8: Internal | F8: AGS IT / DevOps | G8: AGS IT & Infra | H8: Before 21-Sep | I8: Closed
A9: DEP-S1-07 | B9: P5-S1 | C9: Confirmation that Phase 5 = 120 days IN-SCOPE (RBAC in, 4 items out) | D9: Approval / Sign-off | E9: Internal | F9: Suresh Divakaran | G9: TA Head / Leadership | H9: Before 21-Sep | I9: Closed
A10: DEP-S1-08 | B10: P5-S1 | C10: Central logging framework delivered in week 1 of P5-S1 | D10: Predecessor Work | E10: Internal | F10: Dev Team | G10: Dev Team (Internal) | H10: By 25-Sep | I10: In Progress
A11: DEP-S1-09 | B11: P5-S1 | C11: RBAC permission framework delivered in week 1 of P5-S1 | D11: Predecessor Work | E11: Internal | F11: Dev Team | G11: Dev Team (Internal) | H11: By 25-Sep | I11: In Progress
A12: DEP-S1-10 | B12: P5-S1 | C12: Workflow state and transition catalogue per module | D12: Data / Configuration | E12: Internal | F12: TA Head | G12: AGS TA Ops / BA | H12: Before 21-Sep | I12: Not Started | J12: Matrix for the LOB and Assessments to map the list of assessments for each type of Role under LOB
A13: DEP-S1-11 | B13: P5-S1 | C13: Admin role definitions and hierarchy inputs | D13: Approval / Sign-off | E13: Internal | F13: TA Head | G13: TA Head / Leadership | H13: Before 21-Sep | I13: Not Started
A14: DEP-S1-12 | B14: P5-S1 | C14: Admin test accounts and sample user data on STG | D14: Environment | E14: Internal | F14: AGS IT | G14: AGS IT & Infra | H14: Before 21-Sep | I14: Not Started
A15: DEP-S2-01 | B15: P5-S2 | C15: Blacklist reason master list | D15: Data / Configuration | E15: Internal | F15: AGS TA Ops | G15: AGS TA Ops / BA | H15: Before 05-Oct | I15: Not Started
A16: DEP-S2-02 | B16: P5-S2 | C16: Vendor credentials issued - Versant, Oracle, ID Verification | D16: Vendor / 3rd Party | E16: External | F16: Vendor Partners / AGS Procurement | G16: Vendors & Procurement | H16: Before 05-Oct | I16: Not Started
A17: DEP-S2-03 | B17: P5-S2 | C17: Secrets management / vault solution decision and provisioning | D17: Infrastructure | E17: External | F17: AGS Infra & Security | G17: AGS Security, Legal & Compliance | H17: Before 05-Oct | I17: Not Started | J17: DevOps Work. Owned by AGS Team.
A18: DEP-S2-04 | B18: P5-S2 | C18: Encryption key management (KMS) and key rotation policy | D18: Infrastructure | E18: External | F18: AGS Security | G18: AGS Security, Legal & Compliance | H18: Before 05-Oct | I18: Not Started | J18: DevOps Work. Owned by AGS Team.
A19: DEP-S2-05 | B19: P5-S2 | C19: Organizational approval hierarchy data (approvers by level and LOB) | D19: Data / Configuration | E19: Internal | F19: AGS TA Ops / HR | G19: AGS TA Ops / BA | H19: Before 05-Oct | I19: Not Started
A20: DEP-S2-06 | B20: P5-S2 | C20: Security team review of secret handling design | D20: Approval / Sign-off | E20: External | F20: AGS Security | G20: AGS Security, Legal & Compliance | H20: Before 05-Oct | I20: Not Started | J20: DevOps Work. Owned by AGS Team.
A21: DEP-S2-07 | B21: P5-S2 | C21: Versant API access and sandbox environment | D21: Vendor / 3rd Party | E21: External | F21: Versant | G21: Vendors & Procurement | H21: Before 05-Oct | I21: Closed
A22: DEP-S2-08 | B22: P5-S2 | C22: Typing / other assessment tool API access | D22: Vendor / 3rd Party | E22: External | F22: Assessment Vendor | G22: Vendors & Procurement | H22: Before 05-Oct | I22: Closed | J22: SHL, Versant and Panel Only
A23: DEP-S2-09 | B23: P5-S2 | C23: LOB / role to assessment mapping matrix | D23: Data / Configuration | E23: Internal | F23: AGS TA Ops | G23: AGS TA Ops / BA | H23: Before 05-Oct | I23: Not Started
A24: DEP-S2-10 | B24: P5-S2 | C24: Cooling period rules sign-off (SHL 7/30/180, Versant 15/45/180) | D24: Approval / Sign-off | E24: Internal | F24: TA Head / Suresh | G24: TA Head / Leadership | H24: Before 05-Oct | I24: Not Started
A25: DEP-S2-11 | B25: P5-S2 | C25: Voice Fresher Chennai restriction definition and role list | D25: Data / Configuration | E25: Internal | F25: AGS TA Ops | G25: AGS TA Ops / BA | H25: Before 05-Oct | I25: Not Started
A26: DEP-S2-12 | B26: P5-S2 | C26: Secrets vault delivered in week 1 of P5-S2 | D26: Predecessor Work | E26: Internal | F26: Dev Team | G26: Dev Team (Internal) | H26: By 09-Oct | I26: Not Started | J26: DevOps Work. Owned by AGS Team.
A27: DEP-S3-01 | B27: P5-S3 | C27: Final registration field list - mandatory vs optional | D27: Approval / Sign-off | E27: Internal | F27: TA Head / BA | G27: TA Head / Leadership | H27: Before 19-Oct | I27: Not Started
A28: DEP-S3-02 | B28: P5-S3 | C28: Stage-wise editable field matrix (post applicant creation) | D28: Data / Configuration | E28: Internal | F28: AGS TA Ops / BA | G28: AGS TA Ops / BA | H28: Before 19-Oct | I28: Not Started
A29: DEP-S3-03 | B29: P5-S3 | C29: Secure PDF template and branding for profile export | D29: Data / Configuration | E29: Internal | F29: AGS TA / Marketing | G29: AGS Marketing / Web | H29: Before 19-Oct | I29: Not Started
A30: DEP-S3-04 | B30: P5-S3 | C30: Versant API availability (carried from P5-S2) | D30: Vendor / 3rd Party | E30: External | F30: Versant | G30: Vendors & Procurement | H30: Before 19-Oct | I30: Not Started
A31: DEP-S3-05 | B31: P5-S3 | C31: Email templates delivered in P5-S1 | D31: Predecessor Work | E31: Internal | F31: Dev Team | G31: Dev Team (Internal) | H31: Before 19-Oct | I31: Not Started
A32: DEP-S3-06 | B32: P5-S3 | C32: Six mapping scenario definitions (shared with Map Candidate) | D32: Approval / Sign-off | E32: Internal | F32: BA / TA Ops | G32: AGS TA Ops / BA | H32: Before 19-Oct | I32: Not Started
A33: DEP-S3-07 | B33: P5-S3 | C33: Interview slot / calendar master for Walk-In and Online modes | D33: Data / Configuration | E33: Internal | F33: AGS TA Ops | G33: AGS TA Ops / BA | H33: Before 19-Oct | I33: Not Started
A34: DEP-S3-08 | B34: P5-S3 | C34: Sourcing channel master and ERS data feed | D34: Data / Configuration | E34: Internal | F34: AGS TA Ops / ERS Owner | G34: AGS TA Ops / BA | H34: Before 19-Oct | I34: Not Started
A35: DEP-S3-09 | B35: P5-S3 | C35: Standard rejection reason master list | D35: Data / Configuration | E35: Internal | F35: AGS TA Ops | G35: AGS TA Ops / BA | H35: Before 19-Oct | I35: Not Started
A36: DEP-S3-10 | B36: P5-S3 | C36: Oracle requisition validity feed (active vs expired jobs) | D36: Vendor / 3rd Party | E36: External | F36: Oracle Team | G36: Oracle Team | H36: Before 19-Oct | I36: Not Started
A37: DEP-S4-01 | B37: P5-S4 | C37: External Identity Verification API - contract, credentials, rate limits | D37: Vendor / 3rd Party | E37: External | F37: ID Verification Vendor / Procurement | G37: Vendors & Procurement | H37: Before 02-Nov | I37: Not Started
A38: DEP-S4-02 | B38: P5-S4 | C38: Secure document storage with encryption (object store / DMS) | D38: Infrastructure | E38: External | F38: AGS Infra & Security | G38: AGS IT & Infra | H38: Before 02-Nov | I38: Not Started
... A76: DEP-S6-13 | B76: P5-S6 | C76: Hypercare support roster and escalation matrix | D76: Resource | E76: Internal | F76: PM / Dev Team | G76: Dev Team (Internal) | H76: Before 30-Nov | I76: Not Started

Sheet Oracle
B2: Jobs
B3: Create API
B4: Update API
B5: Get All
B6: Get by Id
B7: Candidates
B8: Create API
B9: Update API
B10: Get by Email
B11: Employees
B12: Get by Email

Sheet Deps by Team
A1: Dependencies by Team and Category
A2: Team | B2: Infrastructure | C2: Environment | D2: Data / Configuration | E2: Approval / Sign-off | F2: Vendor / 3rd Party | G2: Predecessor Work | H2: Resource | I2: Total
A3: AGS IT & Infra | B3: =COUNTIFS(Dependencies!$G$3:$G$76,$A3,Dependencies!$D$3:$D$76,B$2) -> 3 | C3: =COUNTIFS(Dependencies!$G$3:$G$76,$A3,Dependencies!$D$3:$D$76,C$2) -> 5 | D3: =COUNTIFS(Dependencies!$G$3:$G$76,$A3,Dependencies!$D$3:$D$76,D$2) -> 0 | E3: =COUNTIFS(Dependencies!$G$3:$G$76,$A3,Dependencies!$D$3:$D$76,E$2) -> 3 | F3: =COUNTIFS(Dependencies!$G$3:$G$76,$A3,Dependencies!$D$3:$D$76,F$2) -> 2 | G3: =COUNTIFS(Dependencies!$G$3:$G$76,$A3,Dependencies!$D$3:$D$76,G$2) -> 0 | H3: =COUNTIFS(Dependencies!$G$3:$G$76,$A3,Dependencies!$D$3:$D$76,H$2) -> 1 | I3: =SUM(B3:H3) -> 14
A4: AGS Security, Legal & Compliance | B4: =COUNTIFS(Dependencies!$G$3:$G$76,$A4,Dependencies!$D$3:$D$76,B$2) -> 4 | C4: =COUNTIFS(Dependencies!$G$3:$G$76,$A4,Dependencies!$D$3:$D$76,C$2) -> 0 | D4: =COUNTIFS(Dependencies!$G$3:$G$76,$A4,Dependencies!$D$3:$D$76,D$2) -> 0 | E4: =COUNTIFS(Dependencies!$G$3:$G$76,$A4,Dependencies!$D$3:$D$76,E$2) -> 3 | F4: =COUNTIFS(Dependencies!$G$3:$G$76,$A4,Dependencies!$D$3:$D$76,F$2) -> 0 | G4: =COUNTIFS(Dependencies!$G$3:$G$76,$A4,Dependencies!$D$3:$D$76,G$2) -> 0 | H4: =COUNTIFS(Dependencies!$G$3:$G$76,$A4,Dependencies!$D$3:$D$76,H$2) -> 0 | I4: =SUM(B4:H4) -> 7
A5: AGS TA Ops / BA | B5: =COUNTIFS(Dependencies!$G$3:$G$76,$A5,Dependencies!$D$3:$D$76,B$2) -> 0 | C5: =COUNTIFS(Dependencies!$G$3:$G$76,$A5,Dependencies!$D$3:$D$76,C$2) -> 0 | D5: =COUNTIFS(Dependencies!$G$3:$G$76,$A5,Dependencies!$D$3:$D$76,D$2) -> 12 | E5: =COUNTIFS(Dependencies!$G$3:$G$76,$A5,Dependencies!$D$3:$D$76,E$2) -> 3 | F5: =COUNTIFS(Dependencies!$G$3:$G$76,$A5,Dependencies!$D$3:$D$76,F$2) -> 0 | G5: =COUNTIFS(Dependencies!$G$3:$G$76,$A5,Dependencies!$D$3:$D$76,G$2) -> 0 | H5: =COUNTIFS(Dependencies!$G$3:$G$76,$A5,Dependencies!$D$3:$D$76,H$2) -> 0 | I5: =SUM(B5:H5) -> 15
